üêætrain_main
    EPOCHS: 15
    BATCH_SIZE: 512
    kifu_dir: None
    size: 9
    use_gpu: True
    rl: False
    window_size: 300000
    network_name: DualNet
    npz_dir: data
    ddp: True
    rl_num: -1
    rl_datetime: 
    input_opt: 
üêætrain_on_gpu_ddp 2024-10-30 17:14:22.702866
    [20241030_171422] device
Traceback (most recent call last):
  File "train.py", line 124, in <module>
  File "/data/student/u2424004/igo/TantamaGo/env/lib/python3.7/site-packages/click/core.py", line 1157, in __call__
  File "/data/student/u2424004/igo/TantamaGo/env/lib/python3.7/site-packages/click/core.py", line 1078, in main
  File "/data/student/u2424004/igo/TantamaGo/env/lib/python3.7/site-packages/click/core.py", line 1434, in invoke
  File "/data/student/u2424004/igo/TantamaGo/env/lib/python3.7/site-packages/click/core.py", line 783, in invoke
  File "train.py", line 115, in train_main
  File "/data/student/u2424004/igo/TantamaGo/nn/learn.py", line 587, in train_on_gpu_ddp
  File "/data/student/u2424004/igo/TantamaGo/env/lib/python3.7/site-packages/torch/cuda/__init__.py", line 552, in current_device
  File "/data/student/u2424004/igo/TantamaGo/env/lib/python3.7/site-packages/torch/cuda/__init__.py", line 229, in _lazy_init
RuntimeError: Unexpected error from cudaGetDeviceCount(). Did you run some cuda functions before calling NumCudaDevices() that might have already set an error? Error 2: out of memory
